2025-08-11 13:17:06,701 [INFO] Lendo arquivo 'Comfaulda/Combined Faults/Unbalance_Horizontal_misalignment/Unbalance_30_g+Hor. Misalignment_0.5_mm/12.97.csv' do bucket 'datalake' no Minio...
2025-08-11 13:17:07,500 [INFO] Arquivo lido com sucesso, 249999 linhas carregadas.
2025-08-11 13:17:08,508 [INFO] Histogramas salvos em 'histograma_datalake.png'.
2025-08-11 13:19:40,488 [INFO] Lendo arquivo 'analise_vendas.csv' do bucket 'datalake' no Minio...
2025-08-11 13:19:40,914 [INFO] Arquivo lido com sucesso, 4 linhas carregadas.
2025-08-11 13:19:41,297 [INFO] Histogramas salvos em 'histograma_datalake.png'.
2025-08-11 13:32:11,427 [INFO] Lendo arquivo 'data/analise_vendas.csv' do bucket 'datalake' no Minio...
2025-08-11 13:32:11,776 [ERROR] Erro ao ler arquivo: datalake/data/analise_vendas.csv
Traceback (most recent call last):
  File "/Users/gabrielazevedo/projects/src/IC/researchers_scripts/minio_loader.py", line 43, in load_dataset
    df = pd.read_csv(s3_path, storage_options=storage_options)
         ^^^^^^^^^^^^^^^^^^^^^^^^^^^^^^^^^^^^^^^^^^^^^^^^^^^^^
  File "/Users/gabrielazevedo/.pyenv/versions/3.11.6/lib/python3.11/site-packages/pandas/io/parsers/readers.py", line 1026, in read_csv
    return _read(filepath_or_buffer, kwds)
           ^^^^^^^^^^^^^^^^^^^^^^^^^^^^^^^
  File "/Users/gabrielazevedo/.pyenv/versions/3.11.6/lib/python3.11/site-packages/pandas/io/parsers/readers.py", line 620, in _read
    parser = TextFileReader(filepath_or_buffer, **kwds)
             ^^^^^^^^^^^^^^^^^^^^^^^^^^^^^^^^^^^^^^^^^^
  File "/Users/gabrielazevedo/.pyenv/versions/3.11.6/lib/python3.11/site-packages/pandas/io/parsers/readers.py", line 1620, in __init__
    self._engine = self._make_engine(f, self.engine)
                   ^^^^^^^^^^^^^^^^^^^^^^^^^^^^^^^^^
  File "/Users/gabrielazevedo/.pyenv/versions/3.11.6/lib/python3.11/site-packages/pandas/io/parsers/readers.py", line 1880, in _make_engine
    self.handles = get_handle(
                   ^^^^^^^^^^^
  File "/Users/gabrielazevedo/.pyenv/versions/3.11.6/lib/python3.11/site-packages/pandas/io/common.py", line 728, in get_handle
    ioargs = _get_filepath_or_buffer(
             ^^^^^^^^^^^^^^^^^^^^^^^^
  File "/Users/gabrielazevedo/.pyenv/versions/3.11.6/lib/python3.11/site-packages/pandas/io/common.py", line 432, in _get_filepath_or_buffer
    ).open()
      ^^^^^^
  File "/Users/gabrielazevedo/.pyenv/versions/3.11.6/lib/python3.11/site-packages/fsspec/core.py", line 147, in open
    return self.__enter__()
           ^^^^^^^^^^^^^^^^
  File "/Users/gabrielazevedo/.pyenv/versions/3.11.6/lib/python3.11/site-packages/fsspec/core.py", line 105, in __enter__
    f = self.fs.open(self.path, mode=mode)
        ^^^^^^^^^^^^^^^^^^^^^^^^^^^^^^^^^^
  File "/Users/gabrielazevedo/.pyenv/versions/3.11.6/lib/python3.11/site-packages/fsspec/spec.py", line 1338, in open
    f = self._open(
        ^^^^^^^^^^^
  File "/Users/gabrielazevedo/.pyenv/versions/3.11.6/lib/python3.11/site-packages/s3fs/core.py", line 720, in _open
    return S3File(
           ^^^^^^^
  File "/Users/gabrielazevedo/.pyenv/versions/3.11.6/lib/python3.11/site-packages/s3fs/core.py", line 2257, in __init__
    super().__init__(
  File "/Users/gabrielazevedo/.pyenv/versions/3.11.6/lib/python3.11/site-packages/fsspec/spec.py", line 1912, in __init__
    self.size = self.details["size"]
                ^^^^^^^^^^^^
  File "/Users/gabrielazevedo/.pyenv/versions/3.11.6/lib/python3.11/site-packages/fsspec/spec.py", line 1925, in details
    self._details = self.fs.info(self.path)
                    ^^^^^^^^^^^^^^^^^^^^^^^
  File "/Users/gabrielazevedo/.pyenv/versions/3.11.6/lib/python3.11/site-packages/fsspec/asyn.py", line 118, in wrapper
    return sync(self.loop, func, *args, **kwargs)
           ^^^^^^^^^^^^^^^^^^^^^^^^^^^^^^^^^^^^^^
  File "/Users/gabrielazevedo/.pyenv/versions/3.11.6/lib/python3.11/site-packages/fsspec/asyn.py", line 103, in sync
    raise return_result
  File "/Users/gabrielazevedo/.pyenv/versions/3.11.6/lib/python3.11/site-packages/fsspec/asyn.py", line 56, in _runner
    result[0] = await coro
                ^^^^^^^^^^
  File "/Users/gabrielazevedo/.pyenv/versions/3.11.6/lib/python3.11/site-packages/s3fs/core.py", line 1492, in _info
    raise FileNotFoundError(path)
FileNotFoundError: datalake/data/analise_vendas.csv
2025-08-11 13:32:52,496 [INFO] Lendo arquivo 'analise_vendas.csv' do bucket 'datalake' no Minio...
2025-08-11 13:32:52,851 [INFO] Arquivo lido com sucesso, 4 linhas carregadas.
2025-08-11 13:32:53,291 [INFO] Histogramas salvos em 'histograma_datalake.png'.
2025-08-11 13:36:54,953 [INFO] Lendo arquivo 'Comfaulda/Combined Faults/Unbalance_Horizontal_misalignment/Unbalance_30_g+Hor. Misalignment_0.5_mm/12.97.csv' do bucket 'datalake' no Minio...
2025-08-11 13:36:55,617 [INFO] Arquivo lido com sucesso, 249999 linhas carregadas.
2025-08-11 13:36:56,505 [INFO] Histogramas salvos em 'histograma_datalake.png'.
